# 捕获异常 ( catch )

编写程序时，在可能出现异常( 编译时不会报错，可能会在运行时发生 )的地方加上检查的代码。过多的分支会导致代码可读性差，因此采用 **异常机制** 。

#### Java 异常处理：

Java采用异常处理机制，将异常处理的程序代码集中在一起，与正常的程序代码分开，使得程序简洁，并易于维护。

## 异常处理机制

* Java 提供的是异常处理的 **catch-throw ( 抓-抛 )** 模型

* Java  程序执行过程中如果出现异常，会自动生成一个异常类对象，该异常对象将被提交给 Java 运行时系统，这个过程称为 **throw ( 抛出 )** 异常

* 如果一个方法内 **抛出** 异常，该异常会被抛到调用方法中。如果异常没有在调用方法中处理，它继续被抛给这个调用方法的 **调用者** 。这个过程将一直继续下去，知道异常被处理。这一过程称为 **捕获异常**

* 如果一个异常回到 main() 方法，并且 main() 方法也不处理，则程序终止运行

* 此机制只能处理 **Exception** ，无法处理 **Error**

  ```java
  /*
  捕获异常
  */
  public class TestException {
  	public static void main(String[] args) {
  	
  		// 用 try{} 括住有可能出现异常的代码段
  		try {
  			System.out.println(3/0);
  		}
  		/*
  	  	  try 后面的 catch 函数用于处理接收到的异常
  	  	  Exception 是所有异常 的父类
  		*/
  		catch (Exception exp) {
  			// Exception.printStackTrace() 输出异常
  			exp.printStackTrace();
  			// Exception.getMessage() 获取异常
  			System.out.println(exp.getMessage());
  		}	
  	}
  }
  ```

#### try-catch-finally 语句

**try-catch-finally** 语句可以一次处理多种异常

```java
/*
  捕获异常
*/
public class TestException {
	
	public static void main(String[] args) {
		
		int index;
	    int[] intArr = new int[] {1,2,3,4};
	    
		/*
		  下面 try{} 中的代码可能会出现 数组越界异常 || 数字运算异常
		*/
		for(index=0; index<6; index++) {
			try {
				System.out.println(intArr[index]/index-1);
			}
		    // ArithmeticException:数字运算异常
			catch (ArithmeticException exp) {
				System.out.print("运算异常：");
				System.out.println(exp.getMessage());
			}
			// ArrayIndexOutOfBoundsException:数组越界异常
			catch (ArrayIndexOutOfBoundsException exp) {
				System.out.print("数组越界异常：");
				System.out.println(exp.getMessage());
			}
            // 最终无条件执行（不论是否抛出异常）
            // 在 IO 操作和 JDBC 中常用
			finally {
				System.out.println("处理完成："+(index+1));
			}
		}
	}
}
```

与其他对象一样，捕获异常时，可以访问异常对象的成员变量或调用它的方法：

* getMessage() : 获取异常事件的描述
* printStactTrace() : 打印异常发生时执行堆栈的内容